<mujoco model="simple_biped">
    <compiler angle="radian" autolimits="true" />
    <visual>
        <map force="0.1" zfar="30"/>
        <rgba haze="0.15 0.25 0.35 1"/>
        <global offwidth="2560" offheight="1440" elevation="-20" azimuth="120"/>
    </visual>

    <default>
        <geom type="mesh" xyaxes="1 0 0 0 1 0" rgba="0.5 0.7 1.0 1"/>
        <position kp="1.8" />
    </default>

    <asset>
        <mesh name="body" file="mesh/body.stl" scale="0.001 0.001 0.001"/>
        <mesh name="leftUpperLeg" file="mesh/leftUpperLeg.stl" scale="0.001 0.001 0.001"/>
        <mesh name="leftLowerLeg" file="mesh/leftLowerLeg.stl" scale="0.001 0.001 0.001"/>
        <mesh name="leftFoot" file="mesh/leftFoot.stl" scale="0.001 0.001 0.001"/>
        <mesh name="rightUpperLeg" file="mesh/rightUpperLeg.stl" scale="0.001 0.001 0.001"/>
        <mesh name="rightLowerLeg" file="mesh/rightLowerLeg.stl" scale="0.001 0.001 0.001"/>
        <mesh name="rightFoot" file="mesh/rightFoot.stl" scale="0.001 0.001 0.001"/>
    </asset>

    <worldbody>
        <geom name="floor" size="0 0 .05" type="plane" condim="3" rgba="0.9 0.9 0.9 1"/>
        <light name="spotlight" mode="targetbodycom" target="body" diffuse=".8 .8 .8" specular="0.3 0.3 0.3" pos="0 -6 4" cutoff="30"/>
        <camera name="track" mode="track" pos="0 -3 1" xyaxes="1 0 0 0 0.2 1" target="body"/>
        <body name="body" pos="0 0 0.508">
            <freejoint  name="root"/>
            <geom mesh="body" density="100"/>
            <body name="leftUpperLeg">
                <joint name="leftHipJoint" axis="0 1 0" pos="-0.08890 -0.00726 -0.117016" range="-0.1 1"/>
                <joint name="leftUpperLegJoint" axis="1 0 0" pos="-0.08890 -0.00726 -0.117016" range="-1.2 1.2"/>
                <geom mesh="leftUpperLeg"/>
                <body name="leftLowerLeg">
                    <joint name="leftLowerLegJoint" axis="1 0 0" pos="-0.08890 -0.00726 -0.33020" range="-1.5 2"/>
                    <geom mesh="leftLowerLeg"/>
                    <body name="leftFoot">
                        <joint name="leftFootJoint" axis="1 0 0" pos="-0.08890 -0.00726 -0.48260" range="-2 2"/>
                        <geom mesh="leftFoot"/>
                        <site name="left_foot_site" pos="-0.10160 0 -0.50800" size="0.01"/>
                    </body>
                </body>
            </body>
            <body name="rightUpperLeg">
                <joint name="rightHipJoint" axis="0 1 0" pos="0.08890 -0.00726 -0.117016" range="-0.1 1"/>
                <joint name="rightUpperLegJoint" axis="1 0 0" pos="0.08890 -0.00726 -0.117016" range="-1.2 1.2"/>
                <geom mesh="rightUpperLeg"/>
                <body name="rightLowerLeg">
                    <joint name="rightLowerLegJoint" axis="1 0 0" pos="0.08890 -0.00726 -0.33020" range="-1.5 2"/>
                    <geom mesh="rightLowerLeg"/>
                    <body name="rightFoot">
                        <joint name="rightFootJoint" axis="1 0 0" pos="0.08890 -0.00726 -0.48260" range="-2 2"/>
                        <geom mesh="rightFoot"/>
                        <site name="right_foot_site" pos="0.10160 0 -0.50800" size="0.01"/>
                    </body>
                </body>
            </body>
        </body>
    </worldbody>

    <actuator>
        <position name="leftHipJoint" joint="leftHipJoint"  />
        <position name="leftUpperLegJoint" joint="leftUpperLegJoint"  />
        <position name="leftLowerLegJoint" joint="leftLowerLegJoint"  />
        <position name="leftFootJoint" joint="leftFootJoint"  />

        <position name="rightHipJoint" joint="rightHipJoint" />
        <position name="rightUpperLegJoint" joint="rightUpperLegJoint"  />
        <position name="rightLowerLegJoint" joint="rightLowerLegJoint"  />
        <position name="rightFootJoint" joint="rightFootJoint" />
    </actuator>

    <keyframe>
        <key
            name="home"
            qpos="0.0122991 0.0473479 0.384688 0.996077 -0.0879596 -0.0075851 0.00597524 0.227775 -0.558918 1.65258 -0.913232 -0.101759 -0.571285 1.66531 -0.916193"
            ctrl="0.177238 -0.576 1.49926 -0.92 -0.177238 -0.576 1.49926 -0.92"
        />
    </keyframe>
</mujoco>