<mujoco model="really_simple_arm">
    <default>
        <!-- convert the Fusion 360 coordinate system to MuJoCo -->
        <geom type="mesh" xyaxes="1 0 0 0 1 0" rgba="0.5 0.7 1.0 1"/>
        <motor  gear="10" />
    </default>
    <asset>
        <!-- Fusion outputs meshes with mm units by default, but must be converted to m in MuJoCo, hence the scaling -->
        <mesh name="body" file="mesh/body.stl" scale="0.001 0.001 0.001"/>

        <mesh name="topLeftLinkage" file="mesh/topLeftLinkage.stl" scale="0.001 0.001 0.001"/>
        <mesh name="upperLeftLeg" file="mesh/upperLeftLeg.stl" scale="0.001 0.001 0.001"/>
        <mesh name="lowerLeftLeg" file="mesh/lowerLeftLeg.stl" scale="0.001 0.001 0.001"/>

        <mesh name="topRightLinkage" file="mesh/topRightLinkage.stl" scale="0.001 0.001 0.001"/>
        <mesh name="upperRightLeg" file="mesh/upperRightLeg.stl" scale="0.001 0.001 0.001"/>
        <mesh name="lowerRightLeg" file="mesh/lowerRightLeg.stl" scale="0.001 0.001 0.001"/>  

    </asset>
    <worldbody>
        <geom name="floor" size="0 0 .05" type="plane" condim="3" rgba="0.9 0.9 0.9 1"/> 
        <light name="spotlight" mode="targetbodycom" target="body" diffuse=".8 .8 .8" specular="0.3 0.3 0.3" pos="0 -6 4" cutoff="30"/>
        <body name="body">
            <freejoint name="root"/>
            <geom mesh="body"/>
            <body name="topLeftLinkage">
                <joint name="leftHipJoint" axis="1 0 0" pos="-0.29845 0.10160  0.587532" range="-45 45"/>
                <geom mesh="topLeftLinkage"/>
                <body name="upperLeftLeg">
                    <joint name="upperLeftLegJoint" axis="1 0 0" pos="-0.29845 0.10160  0.384332"/>
                    <geom mesh="upperLeftLeg"/>
                    <body name="lowerLeftLeg">
                        <joint name="lowerLeftLegJoint" axis="1 0 0" pos="-0.29845 0.10160  0.181132"/>
                        <geom mesh="lowerLeftLeg"/>
                    </body>
                </body>
            </body>
            <body name="topRightLinkage">
                <joint name="rightHipJoint" axis="1 0 0" pos="0.00635 0.10160  0.587532"/>
                <geom mesh="topRightLinkage"/>
                <body name="upperRightLeg">
                     <joint name="upperRightLegJoint" axis="1 0 0" pos="0.00635 0.10160  0.384332"/>
                    <geom mesh="upperRightLeg"/>
                    <body name="lowerRightLeg">
                        <joint name="lowerRightLegJoint" axis="1 0 0" pos="0.00635 0.10160  0.181132"/>
                        <geom mesh="lowerRightLeg"/>
                    </body>
                </body>
            </body>
        </body>
    </worldbody>

    <actuator>
        <motor name="leftHipJoint" joint="leftHipJoint" />
        <motor name="upperLeftLegJoint" joint="upperLeftLegJoint" />
        <motor name="lowerLeftLegJoint" joint="lowerLeftLegJoint" />

        <motor name="rightHipJoint" joint="rightHipJoint" />
        <motor name="upperRightLegJoint" joint="upperRightLegJoint" />
        <motor name="lowerRightLegJoint" joint="lowerRightLegJoint" />
    </actuator>
</mujoco>